Workbook

Sheet Read me
A1: BusinessIdea.io writing sheet
A3: 1. Open the Batch Prompts page, tap Copy on a batch and paste it into any writing tool. Fresh chat for every batch.
A4: 2. Copy the answer with the code block's own copy button.
A5: 3. Paste it into the Paste tab, column A, in the first empty cell. Paste nothing anywhere else.
A6: 4. Column B says OK, WRONG FIELD COUNT or NO END. Red rows: ask the tool to rewrite that idea, paste the new line below, and delete the red one.
A7: 5. Type next in the tool for the next subcategory (5 per batch). AI Studio: type all for all 50 at once. If it stops halfway, type continue.
A8: 6. In the Batches tab, write which account took the batch and set Status. Column G counts the OK ideas for that batch (50 = complete).
A9: 7. The Ideas tab fills itself with every OK row split into 31 columns. To upload: File > Download > CSV while the Ideas tab is open.
A11: Do not type in the Ideas tab or in columns B to D of the Paste tab: they are formulas.

Sheet Paste
A1: Paste rows here (column A only) | B1: Check | C1: Idea code | D1: Duplicate | F1: Summary
B2: =ARRAYFORMULA(IF(A2:A="",,IF((LEN(A2:A)-LEN(SUBSTITUTE(A2:A," | ","")))/3<>30,"WRONG FIELD COUNT",IF(RIGHT(TRIM(A2:A),3)<>"END","NO END","OK")))) | C2: =ARRAYFORMULA(IF(A2:A="",,IFERROR(REGEXEXTRACT(A2:A,"C[0-9]{3}-S[0-9]{2}-I[0-9]{2}"),"NO CODE"))) | D2: =ARRAYFORMULA(IF(C2:C="",,IF(COUNTIF(C2:C,C2:C)>1,"DUPLICATE",))) | F2: OK ideas | G2: =COUNTIF(B2:B,"OK")
F3: Rows with a problem | G3: =COUNTA(A2:A)-G2
F4: Duplicate codes | G4: =COUNTIF(D2:D,"DUPLICATE")
F5: Target | G5: 10000

Sheet Ideas
A1: code | B1: title | C1: slug | D1: hook | E1: summary | F1: what_it_is | G1: who_pays_you | H1: how_money_comes | I1: what_you_need | J1: step1 | K1: step2 | L1: step3 | M1: step4 | N1: step5 | O1: what_hurts | P1: verdict | Q1: faq1_q | R1: faq1_a | S1: faq2_q | T1: faq2_a | U1: faq3_q | V1: faq3_a | W1: validate_prompt | X1: investment_band | Y1: gender_fit | Z1: life_stage | AA1: place | AB1: work_mode | AC1: time_needed | AD1: skill_level | AE1: end_marker
A2: =ARRAYFORMULA(IFERROR(SPLIT(FILTER(Paste!A2:A,Paste!B2:B="OK")," | ",FALSE,FALSE)))

Sheet Batches
A1: Batch | B1: Category | C1: Category name | D1: Subcategories | E1: Account | F1: Status | G1: OK ideas (of 50) | H1: Notes
A2: B001 | B2: C001 | C2: Work From Home Business Ideas | D2: Home Cooked Meal Subscription, After School Online Tuition, Catalog Reselling From Home, Home Visit Beauty Service, Website and Blog Writing | F2: done | G2: =SUMPRODUCT((Paste!$B$2:$B$20000="OK")*REGEXMATCH(Paste!$C$2:$C$20000&"","^C001-S0[1-5]-I")) | H2: C001 S01 to S05 already in the repo
A3: B002 | B3: C001 | C3: Work From Home Business Ideas | D3: Small Shop Page Handling, Homemade Candle and Soap, Remote Admin Support, Printable and Digital File Selling, Live Online Workshop | F3: todo | G3: =SUMPRODUCT((Paste!$B$2:$B$20000="OK")*REGEXMATCH(Paste!$C$2:$C$20000&"","^C001-S(0[6-9]|10)-I"))
A4: B003 | B4: C002 | C4: Side Hustle Business Ideas | D4: Evening Tuition Side Work, Weekend Food Stall, Social App Product Reselling, Spare Time Design Service, Society Service Side Work | F4: todo | G4: =SUMPRODUCT((Paste!$B$2:$B$20000="OK")*REGEXMATCH(Paste!$C$2:$C$20000&"","^C002-S0[1-5]-I"))
A5: B004 | B5: C002 | C5: Side Hustle Business Ideas | D5: Festival Season Extra Work, Delivery Shift Side Work, Spare Time Content Service, Home Baking Order Side Work, Local Shop Support Side Work | F5: todo | G5: =SUMPRODUCT((Paste!$B$2:$B$20000="OK")*REGEXMATCH(Paste!$C$2:$C$20000&"","^C002-S(0[6-9]|10)-I"))
A6: B005 | B6: C003 | C6: Part Time Business Ideas | D6: Morning Meal Round, After Office Coaching Batch, Weekend Market Stall, Part Time Shop Accounts Help, Evening Hobby Batch | F6: todo | G6: =SUMPRODUCT((Paste!$B$2:$B$20000="OK")*REGEXMATCH(Paste!$C$2:$C$20000&"","^C003-S0[1-5]-I"))
A7: B006 | B7: C003 | C7: Part Time Business Ideas | D7: Part Time Event Photography, Weekend Catering Order, Part Time Online Selling, School Gate Help Service, Part Time Repair Visit | F7: todo | G7: =SUMPRODUCT((Paste!$B$2:$B$20000="OK")*REGEXMATCH(Paste!$C$2:$C$20000&"","^C003-S(0[6-9]|10)-I"))
A8: B007 | B8: C004 | C8: Online Business Ideas | D8: Own Brand Online Store, Marketplace Seller Account, Online Course Selling, Niche Information Website, Remote Client Service | F8: todo | G8: =SUMPRODUCT((Paste!$B$2:$B$20000="OK")*REGEXMATCH(Paste!$C$2:$C$20000&"","^C004-S0[1-5]-I"))
A9: B008 | B9: C004 | C9: Online Business Ideas | D9: WhatsApp and Instagram Shop, Print on Demand Product, Paid Online Community, Digital Download Shop, Online Booking Service | F9: todo | G9: =SUMPRODUCT((Paste!$B$2:$B$20000="OK")*REGEXMATCH(Paste!$C$2:$C$20000&"","^C004-S(0[6-9]|10)-I"))
A10: B009 | B10: C005 | C10: Home Based Business Ideas | D10: Home Tailoring Work, Home Pickle and Papad, Home Beauty Studio, Home Tuition Batch, Home Garment Making | F10: todo | G10: =SUMPRODUCT((Paste!$B$2:$B$20000="OK")*REGEXMATCH(Paste!$C$2:$C$20000&"","^C005-S0[1-5]-I"))
A11: B010 | B11: C005 | C11: Home Based Business Ideas | D11: Home Packed Food Brand, Home Child Care, Home Jewellery Making, Home Computer Class, Home Wash and Iron | F11: todo | G11: =SUMPRODUCT((Paste!$B$2:$B$20000="OK")*REGEXMATCH(Paste!$C$2:$C$20000&"","^C005-S(0[6-9]|10)-I"))
A12: B011 | B12: C006 | C12: Women Friendly Business Ideas | D12: Women Led Home Food, Women Led Beauty Work, Women Led Stitching Work, Homemaker Reselling, Women Led Teaching From Home | F12: todo | G12: =SUMPRODUCT((Paste!$B$2:$B$20000="OK")*REGEXMATCH(Paste!$C$2:$C$20000&"","^C006-S0[1-5]-I"))
A13: B012 | B13: C006 | C13: Women Friendly Business Ideas | D13: Women Led Craft Brand, Women Group Catering, Women Wellness Service, Women Led Kids Class, Homemaker Online Service | F13: todo | G13: =SUMPRODUCT((Paste!$B$2:$B$20000="OK")*REGEXMATCH(Paste!$C$2:$C$20000&"","^C006-S(0[6-9]|10)-I"))
A14: B013 | B14: C007 | C14: Student Business Ideas | D14: Study Notes Selling, Student Freelance Skill, College Event Coverage, Student Social Selling, Peer Tutoring by Students | F14: todo | G14: =SUMPRODUCT((Paste!$B$2:$B$20000="OK")*REGEXMATCH(Paste!$C$2:$C$20000&"","^C007-S0[1-5]-I"))
A15: B014 | B15: C007 | C15: Student Business Ideas | D15: Campus Snack Selling, Student Creator Channel, College Fest Stall, Student Page Handling, Campus Print and Design Service | F15: todo | G15: =SUMPRODUCT((Paste!$B$2:$B$20000="OK")*REGEXMATCH(Paste!$C$2:$C$20000&"","^C007-S(0[6-9]|10)-I"))
A16: B015 | B16: C008 | C16: Senior Citizen Business Ideas | D16: Retired Teacher Class, Experience Based Advice Service, Senior Home Kitchen Brand, Retired Society Service, Hobby Teaching by Seniors | F16: todo | G16: =SUMPRODUCT((Paste!$B$2:$B$20000="OK")*REGEXMATCH(Paste!$C$2:$C$20000&"","^C008-S0[1-5]-I"))
A17: B016 | B17: C008 | C17: Senior Citizen Business Ideas | D17: Senior Plant Nursery, Retired Accounts Help, Senior Writing and Editing, Senior Led Local Walks, Career Mentoring by Seniors | F17: todo | G17: =SUMPRODUCT((Paste!$B$2:$B$20000="OK")*REGEXMATCH(Paste!$C$2:$C$20000&"","^C008-S(0[6-9]|10)-I"))
A18: B017 | B18: C009 | C18: Village and Small Town Business Ideas | D18: Village Daily Needs Shop, Small Town Tuition Centre, Village Milk Collection, Small Town Beauty Parlour, Farm Input Retail Shop | F18: done | G18: =SUMPRODUCT((Paste!$B$2:$B$20000="OK")*REGEXMATCH(Paste!$C$2:$C$20000&"","^C009-S0[1-5]-I")) | H18: C009 already in the repo
A19: B018 | B19: C009 | C19: Village and Small Town Business Ideas | D19: Village Spice and Flour Mill, Small Town Phone Repair, Village Function Catering, Town Two Wheeler Workshop, Small Town Passenger Transport | F19: done | G19: =SUMPRODUCT((Paste!$B$2:$B$20000="OK")*REGEXMATCH(Paste!$C$2:$C$20000&"","^C009-S(0[6-9]|10)-I")) | H19: C009 already in the repo
A20: B019 | B20: C010 | C20: Local Service Business Ideas | D20: Neighbourhood Home Help, Building Upkeep Service, Local Parcel Movement, Doorstep Grooming Service, Local Print and Copy Shop | F20: todo | G20: =SUMPRODUCT((Paste!$B$2:$B$20000="OK")*REGEXMATCH(Paste!$C$2:$C$20000&"","^C010-S0[1-5]-I"))
A21: B020 | B21: C010 | C21: Local Service Business Ideas | D21: Nearby Appliance Care, Local Tutor Network, Area Meal Delivery Kitchen, Local Function Support, Market Day Service | F21: todo | G21: =SUMPRODUCT((Paste!$B$2:$B$20000="OK")*REGEXMATCH(Paste!$C$2:$C$20000&"","^C010-S(0[6-9]|10)-I"))
A22: B021 | B22: C011 | C22: Skill Based Business Ideas | D22: Trade Skill Site Work, Paid Skill Teaching, Maker Skill Product, Repair Skill Visit, Beauty Skill Booking | F22: todo | G22: =SUMPRODUCT((Paste!$B$2:$B$20000="OK")*REGEXMATCH(Paste!$C$2:$C$20000&"","^C011-S0[1-5]-I"))
A23: B022 | B23: C011 | C23: Skill Based Business Ideas | D23: Cooking Skill Order, Digital Skill Client Work, Language Skill Class, Fitness Skill Session, Craft Skill Product | F23: todo | G23: =SUMPRODUCT((Paste!$B$2:$B$20000="OK")*REGEXMATCH(Paste!$C$2:$C$20000&"","^C011-S(0[6-9]|10)-I"))
A24: B023 | B24: C012 | C24: Freelance Business Ideas | D24: Freelance Article Client, Freelance Design Project, Freelance Video Edit, Freelance Website Project, Freelance Marketing Retainer | F24: todo | G24: =SUMPRODUCT((Paste!$B$2:$B$20000="OK")*REGEXMATCH(Paste!$C$2:$C$20000&"","^C012-S0[1-5]-I"))
A25: B024 | B25: C012 | C25: Freelance Business Ideas | D25: Freelance Translation Work, Freelance Voice Over, Freelance Coding Project, Freelance Remote Support, Freelance Advice Call | F25: todo | G25: =SUMPRODUCT((Paste!$B$2:$B$20000="OK")*REGEXMATCH(Paste!$C$2:$C$20000&"","^C012-S(0[6-9]|10)-I"))
A26: B025 | B26: C013 | C26: Reselling Business Ideas | D26: Fashion Catalog Reselling, Beauty Item Reselling, Home Utility Reselling, Kids Item Reselling, WhatsApp Group Reselling | F26: todo | G26: =SUMPRODUCT((Paste!$B$2:$B$20000="OK")*REGEXMATCH(Paste!$C$2:$C$20000&"","^C013-S0[1-5]-I"))
A27: B026 | B27: C013 | C27: Reselling Business Ideas | D27: Closet and Thrift Reselling, Wholesale Lot to Local Sale, Festival Goods Reselling, Hostel Needs Reselling, Daily Needs Basket Reselling | F27: todo | G27: =SUMPRODUCT((Paste!$B$2:$B$20000="OK")*REGEXMATCH(Paste!$C$2:$C$20000&"","^C013-S(0[6-9]|10)-I"))
A28: B027 | B28: C014 | C28: Childcare and Parenting Support Business Ideas | D28: Home Daycare Group, After School Child Watch, Baby Care Visit Service, Parent Child Activity Batch, Kids Birthday Support | F28: todo | G28: =SUMPRODUCT((Paste!$B$2:$B$20000="OK")*REGEXMATCH(Paste!$C$2:$C$20000&"","^C014-S0[1-5]-I"))
A29: B028 | B29: C014 | C29: Childcare and Parenting Support Business Ideas | D29: School Van Route, Tuition With Child Watch, New Mother Home Support, Kids Hobby Group, Parent Learning Kit | F29: todo | G29: =SUMPRODUCT((Paste!$B$2:$B$20000="OK")*REGEXMATCH(Paste!$C$2:$C$20000&"","^C014-S(0[6-9]|10)-I"))
A30: B029 | B30: C015 | C30: Printing and Signage Business Ideas | D30: Copy and Print Shop, Wedding Card Print, Banner and Flex Print, Custom Apparel Print, Label and Sticker Print | F30: todo | G30: =SUMPRODUCT((Paste!$B$2:$B$20000="OK")*REGEXMATCH(Paste!$C$2:$C$20000&"","^C015-S0[1-5]-I"))
A31: B030 | B31: C015 | C31: Printing and Signage Business Ideas | D31: Name Plate and Stamp Shop, Photo Book Print, School Print Job, Vehicle Sticker and Graphics, Pack Print for Small Brands | F31: todo | G31: =SUMPRODUCT((Paste!$B$2:$B$20000="OK")*REGEXMATCH(Paste!$C$2:$C$20000&"","^C015-S(0[6-9]|10)-I"))
A32: B031 | B32: C016 | C32: Food Business Ideas | D32: Daily Dabba Supply, Namkeen Making and Packing, Regional Thali Meal, Office Lunch Contract, Festival Food Order | F32: todo | G32: =SUMPRODUCT((Paste!$B$2:$B$20000="OK")*REGEXMATCH(Paste!$C$2:$C$20000&"","^C016-S0[1-5]-I"))
A33: B032 | B33: C016 | C33: Food Business Ideas | D33: Special Diet Meal Kitchen, Night Eatery Food, House Party Food Order, Travel Stop Food, Hostel and Canteen Meal | F33: todo | G33: =SUMPRODUCT((Paste!$B$2:$B$20000="OK")*REGEXMATCH(Paste!$C$2:$C$20000&"","^C016-S(0[6-9]|10)-I"))
A34: B033 | B34: C017 | C34: Home Kitchen Food Business Ideas | D34: Homemade Pickle Brand, Papad Making at Home, Home Spice Mix Brand, Homemade Sweet Box, Batter and Ready Mix | F34: todo | G34: =SUMPRODUCT((Paste!$B$2:$B$20000="OK")*REGEXMATCH(Paste!$C$2:$C$20000&"","^C017-S0[1-5]-I"))
A35: B034 | B35: C017 | C35: Home Kitchen Food Business Ideas | D35: Home Chocolate Making, Dry Snack Packing at Home, Chutney and Sauce Making, Festival Food Hamper, Single Dish Home Kitchen | F35: todo | G35: =SUMPRODUCT((Paste!$B$2:$B$20000="OK")*REGEXMATCH(Paste!$C$2:$C$20000&"","^C017-S(0[6-9]|10)-I"))
A36: B035 | B36: C018 | C36: Street Food Business Ideas | D36: Chaat and Snack Cart, Momos and Dumpling Stall, Roll and Wrap Stall, South Indian Tiffin Stall, Juice and Shake Cart | F36: todo | G36: =SUMPRODUCT((Paste!$B$2:$B$20000="OK")*REGEXMATCH(Paste!$C$2:$C$20000&"","^C018-S0[1-5]-I"))
A37: B036 | B37: C018 | C37: Street Food Business Ideas | D37: Tea Stall, Indo Chinese Stall, Evening Fry Snack Stall, Egg and Non Veg Street Stall, Seasonal Street Snack | F37: todo | G37: =SUMPRODUCT((Paste!$B$2:$B$20000="OK")*REGEXMATCH(Paste!$C$2:$C$20000&"","^C018-S(0[6-9]|10)-I"))
A38: B037 | B38: C019 | C38: Bakery and Confectionery Business Ideas | D38: Custom Celebration Cake, Bread and Bun Bakery, Cookie and Biscuit Batch, Eggless Bake House, Dessert Box Bakery | F38: todo | G38: =SUMPRODUCT((Paste!$B$2:$B$20000="OK")*REGEXMATCH(Paste!$C$2:$C$20000&"","^C019-S0[1-5]-I"))
A39: B038 | B39: C019 | C39: Bakery and Confectionery Business Ideas | D39: Bakery Supply to Cafes, Wedding Dessert Table, Millet and Healthy Bake, Shop Counter Bakery, Festival Gift Bake | F39: todo | G39: =SUMPRODUCT((Paste!$B$2:$B$20000="OK")*REGEXMATCH(Paste!$C$2:$C$20000&"","^C019-S(0[6-9]|10)-I"))
A40: B039 | B40: C020 | C40: Catering Business Ideas | D40: Wedding Meal Catering, Small House Party Catering, Office Gathering Catering, Religious Function Meal, Live Food Counter | F40: todo | G40: =SUMPRODUCT((Paste!$B$2:$B$20000="OK")*REGEXMATCH(Paste!$C$2:$C$20000&"","^C020-S0[1-5]-I"))
...

Sheet Format check
A1: C000-S00-I01 | test title | END | B1: =SPLIT(A1," | ",FALSE,FALSE)
A3: This tab only proves the split formula works after upload. Leave it.
